<?xml version="1.0"?>
<robot name="bmark">

    <link name="bmark_base"/>
    <link name="bmark_l"/>

    <joint name="joint_a1" type="revolute">
        <origin rpy="0 0 0" xyz="0 0 0"/>
        <parent link="bmark_base"/>
        <child link="phi_l"/>
        <axis xyz="0 0 1"/>
    </joint>

    <ros2_control name="bmark" type="system">
        <hardware>
            <plugin>fake_components/GenericSystem</plugin>
        </hardware>
        <joint name="joint_a1">
            <command_interface name="position" />
            <state_interface name="position"/>
        </joint>
    </ros2_control>
</robot>
